[2024-04-05 17:44:29,727][flwr][INFO] - Starting Flower simulation, config: ServerConfig(num_rounds=10, round_timeout=None)
[2024-04-05 17:44:33,335][flwr][INFO] - Flower VCE: Ray initialized with resources: {'object_store_memory': 37035218534.0, 'node:127.0.0.1': 1.0, 'CPU': 32.0, 'GPU': 1.0, 'memory': 76415509914.0}
[2024-04-05 17:44:33,338][flwr][INFO] - Initializing global parameters
[2024-04-05 17:44:33,339][flwr][INFO] - Requesting initial parameters from one random client
[2024-04-05 17:44:35,923][flwr][INFO] - Received initial parameters from one random client
[2024-04-05 17:44:35,925][flwr][INFO] - Evaluating initial parameters
[2024-04-05 17:44:45,062][flwr][INFO] - initial parameters (loss, other metrics): 182.195734500885, {'accuracy': 0.0893}
[2024-04-05 17:44:45,064][flwr][INFO] - FL starting
[2024-04-05 17:44:45,065][flwr][DEBUG] - fit_round 1: strategy sampled 10 clients (out of 25)
[2024-04-05 17:45:54,326][flwr][ERROR] - [36mray::launch_and_fit()[39m (pid=2480, ip=127.0.0.1)
  File "C:\Users\Admin\anaconda3\envs\flwrpytorch\lib\multiprocessing\queues.py", line 108, in get
    raise Empty
_queue.Empty

The above exception was the direct cause of the following exception:

[36mray::launch_and_fit()[39m (pid=2480, ip=127.0.0.1)
  File "python\ray\_raylet.pyx", line 633, in ray._raylet.execute_task
  File "python\ray\_raylet.pyx", line 674, in ray._raylet.execute_task
  File "python\ray\_raylet.pyx", line 640, in ray._raylet.execute_task
  File "python\ray\_raylet.pyx", line 644, in ray._raylet.execute_task
  File "C:\Users\Admin\anaconda3\envs\flwrpytorch\lib\site-packages\flwr\simulation\ray_transport\ray_client_proxy.py", line 148, in launch_and_fit
    return maybe_call_fit(
  File "C:\Users\Admin\anaconda3\envs\flwrpytorch\lib\site-packages\flwr\client\client.py", line 184, in maybe_call_fit
    return client.fit(fit_ins)
  File "C:\Users\Admin\anaconda3\envs\flwrpytorch\lib\site-packages\flwr\client\app.py", line 297, in _fit
    results = self.numpy_client.fit(parameters, ins.config)  # type: ignore
  File "c:\Users\Admin\Desktop\Vipul\Part-II\client.py", line 58, in fit
    train(self.model, self.trainloader, optim, epochs, self.device)
  File "c:\Users\Admin\Desktop\Vipul\Part-II\model.py", line 34, in train
    for images, labels in trainloader:
  File "C:\Users\Admin\anaconda3\envs\flwrpytorch\lib\site-packages\torch\utils\data\dataloader.py", line 628, in __next__
    data = self._next_data()
  File "C:\Users\Admin\anaconda3\envs\flwrpytorch\lib\site-packages\torch\utils\data\dataloader.py", line 1316, in _next_data
    idx, data = self._get_data()
  File "C:\Users\Admin\anaconda3\envs\flwrpytorch\lib\site-packages\torch\utils\data\dataloader.py", line 1282, in _get_data
    success, data = self._try_get_data()
  File "C:\Users\Admin\anaconda3\envs\flwrpytorch\lib\site-packages\torch\utils\data\dataloader.py", line 1133, in _try_get_data
    raise RuntimeError('DataLoader worker (pid(s) {}) exited unexpectedly'.format(pids_str)) from e
RuntimeError: DataLoader worker (pid(s) 17692) exited unexpectedly
