[2023-11-07 08:45:06,615][flwr][INFO] - Starting Flower simulation, config: ServerConfig(num_rounds=10, round_timeout=None)
[2023-11-07 08:45:10,460][flwr][INFO] - Flower VCE: Ray initialized with resources: {'node:127.0.0.1': 1.0, 'CPU': 32.0, 'object_store_memory': 37650756403.0, 'GPU': 1.0, 'memory': 77851764941.0}
[2023-11-07 08:45:10,460][flwr][INFO] - Initializing global parameters
[2023-11-07 08:45:10,460][flwr][INFO] - Requesting initial parameters from one random client
[2023-11-07 08:45:12,656][flwr][INFO] - Received initial parameters from one random client
[2023-11-07 08:45:12,656][flwr][INFO] - Evaluating initial parameters
[2023-11-07 08:45:20,465][flwr][INFO] - initial parameters (loss, other metrics): 181.8379681110382, {'accuracy': 0.1312}
[2023-11-07 08:45:20,480][flwr][INFO] - FL starting
[2023-11-07 08:45:20,480][flwr][DEBUG] - fit_round 1: strategy sampled 10 clients (out of 100)
[2023-11-07 08:45:50,831][flwr][DEBUG] - fit_round 1 received 10 results and 0 failures
[2023-11-07 08:45:50,873][flwr][WARNING] - No fit_metrics_aggregation_fn provided
[2023-11-07 08:45:54,212][flwr][INFO] - fit progress: (1, 176.6723518371582, {'accuracy': 0.2802}, 33.7424531)
[2023-11-07 08:45:54,212][flwr][DEBUG] - evaluate_round 1: strategy sampled 15 clients (out of 100)
[2023-11-07 08:46:07,637][flwr][ERROR] - [36mray::launch_and_evaluate()[39m (pid=20732, ip=127.0.0.1)
  File "C:\Users\Admin\anaconda3\envs\flwrpytorch\lib\multiprocessing\queues.py", line 108, in get
    raise Empty
_queue.Empty

The above exception was the direct cause of the following exception:

[36mray::launch_and_evaluate()[39m (pid=20732, ip=127.0.0.1)
  File "python\ray\_raylet.pyx", line 633, in ray._raylet.execute_task
  File "python\ray\_raylet.pyx", line 674, in ray._raylet.execute_task
  File "python\ray\_raylet.pyx", line 640, in ray._raylet.execute_task
  File "python\ray\_raylet.pyx", line 644, in ray._raylet.execute_task
  File "C:\Users\Admin\anaconda3\envs\flwrpytorch\lib\site-packages\flwr\simulation\ray_transport\ray_client_proxy.py", line 160, in launch_and_evaluate
    return maybe_call_evaluate(
  File "C:\Users\Admin\anaconda3\envs\flwrpytorch\lib\site-packages\flwr\client\client.py", line 205, in maybe_call_evaluate
    return client.evaluate(evaluate_ins)
  File "C:\Users\Admin\anaconda3\envs\flwrpytorch\lib\site-packages\flwr\client\app.py", line 321, in _evaluate
    results = self.numpy_client.evaluate(parameters, ins.config)  # type: ignore
  File "c:\Users\Admin\Desktop\Vipul\drive-download-20230927T134210Z-001\client.py", line 79, in evaluate
    loss, accuracy = test(self.model, self.valloader, self.device)
  File "c:\Users\Admin\Desktop\Vipul\drive-download-20230927T134210Z-001\model.py", line 57, in test
    for data in testloader:
  File "C:\Users\Admin\anaconda3\envs\flwrpytorch\lib\site-packages\torch\utils\data\dataloader.py", line 628, in __next__
    data = self._next_data()
  File "C:\Users\Admin\anaconda3\envs\flwrpytorch\lib\site-packages\torch\utils\data\dataloader.py", line 1316, in _next_data
    idx, data = self._get_data()
  File "C:\Users\Admin\anaconda3\envs\flwrpytorch\lib\site-packages\torch\utils\data\dataloader.py", line 1282, in _get_data
    success, data = self._try_get_data()
  File "C:\Users\Admin\anaconda3\envs\flwrpytorch\lib\site-packages\torch\utils\data\dataloader.py", line 1133, in _try_get_data
    raise RuntimeError('DataLoader worker (pid(s) {}) exited unexpectedly'.format(pids_str)) from e
RuntimeError: DataLoader worker (pid(s) 16652) exited unexpectedly
[2023-11-07 08:46:07,879][flwr][ERROR] - [36mray::launch_and_evaluate()[39m (pid=15080, ip=127.0.0.1)
  File "C:\Users\Admin\anaconda3\envs\flwrpytorch\lib\multiprocessing\queues.py", line 108, in get
    raise Empty
_queue.Empty

The above exception was the direct cause of the following exception:

[36mray::launch_and_evaluate()[39m (pid=15080, ip=127.0.0.1)
  File "python\ray\_raylet.pyx", line 633, in ray._raylet.execute_task
  File "python\ray\_raylet.pyx", line 674, in ray._raylet.execute_task
  File "python\ray\_raylet.pyx", line 640, in ray._raylet.execute_task
  File "python\ray\_raylet.pyx", line 644, in ray._raylet.execute_task
  File "C:\Users\Admin\anaconda3\envs\flwrpytorch\lib\site-packages\flwr\simulation\ray_transport\ray_client_proxy.py", line 160, in launch_and_evaluate
    return maybe_call_evaluate(
  File "C:\Users\Admin\anaconda3\envs\flwrpytorch\lib\site-packages\flwr\client\client.py", line 205, in maybe_call_evaluate
    return client.evaluate(evaluate_ins)
  File "C:\Users\Admin\anaconda3\envs\flwrpytorch\lib\site-packages\flwr\client\app.py", line 321, in _evaluate
    results = self.numpy_client.evaluate(parameters, ins.config)  # type: ignore
  File "c:\Users\Admin\Desktop\Vipul\drive-download-20230927T134210Z-001\client.py", line 79, in evaluate
    loss, accuracy = test(self.model, self.valloader, self.device)
  File "c:\Users\Admin\Desktop\Vipul\drive-download-20230927T134210Z-001\model.py", line 57, in test
    for data in testloader:
  File "C:\Users\Admin\anaconda3\envs\flwrpytorch\lib\site-packages\torch\utils\data\dataloader.py", line 628, in __next__
    data = self._next_data()
  File "C:\Users\Admin\anaconda3\envs\flwrpytorch\lib\site-packages\torch\utils\data\dataloader.py", line 1316, in _next_data
    idx, data = self._get_data()
  File "C:\Users\Admin\anaconda3\envs\flwrpytorch\lib\site-packages\torch\utils\data\dataloader.py", line 1282, in _get_data
    success, data = self._try_get_data()
  File "C:\Users\Admin\anaconda3\envs\flwrpytorch\lib\site-packages\torch\utils\data\dataloader.py", line 1133, in _try_get_data
    raise RuntimeError('DataLoader worker (pid(s) {}) exited unexpectedly'.format(pids_str)) from e
RuntimeError: DataLoader worker (pid(s) 3672) exited unexpectedly
[2023-11-07 08:46:08,017][flwr][ERROR] - [36mray::launch_and_evaluate()[39m (pid=22244, ip=127.0.0.1)
  File "C:\Users\Admin\anaconda3\envs\flwrpytorch\lib\multiprocessing\queues.py", line 108, in get
    raise Empty
_queue.Empty

The above exception was the direct cause of the following exception:

[36mray::launch_and_evaluate()[39m (pid=22244, ip=127.0.0.1)
  File "python\ray\_raylet.pyx", line 633, in ray._raylet.execute_task
  File "python\ray\_raylet.pyx", line 674, in ray._raylet.execute_task
  File "python\ray\_raylet.pyx", line 640, in ray._raylet.execute_task
  File "python\ray\_raylet.pyx", line 644, in ray._raylet.execute_task
  File "C:\Users\Admin\anaconda3\envs\flwrpytorch\lib\site-packages\flwr\simulation\ray_transport\ray_client_proxy.py", line 160, in launch_and_evaluate
    return maybe_call_evaluate(
  File "C:\Users\Admin\anaconda3\envs\flwrpytorch\lib\site-packages\flwr\client\client.py", line 205, in maybe_call_evaluate
    return client.evaluate(evaluate_ins)
  File "C:\Users\Admin\anaconda3\envs\flwrpytorch\lib\site-packages\flwr\client\app.py", line 321, in _evaluate
    results = self.numpy_client.evaluate(parameters, ins.config)  # type: ignore
  File "c:\Users\Admin\Desktop\Vipul\drive-download-20230927T134210Z-001\client.py", line 79, in evaluate
    loss, accuracy = test(self.model, self.valloader, self.device)
  File "c:\Users\Admin\Desktop\Vipul\drive-download-20230927T134210Z-001\model.py", line 57, in test
    for data in testloader:
  File "C:\Users\Admin\anaconda3\envs\flwrpytorch\lib\site-packages\torch\utils\data\dataloader.py", line 628, in __next__
    data = self._next_data()
  File "C:\Users\Admin\anaconda3\envs\flwrpytorch\lib\site-packages\torch\utils\data\dataloader.py", line 1316, in _next_data
    idx, data = self._get_data()
  File "C:\Users\Admin\anaconda3\envs\flwrpytorch\lib\site-packages\torch\utils\data\dataloader.py", line 1282, in _get_data
    success, data = self._try_get_data()
  File "C:\Users\Admin\anaconda3\envs\flwrpytorch\lib\site-packages\torch\utils\data\dataloader.py", line 1133, in _try_get_data
    raise RuntimeError('DataLoader worker (pid(s) {}) exited unexpectedly'.format(pids_str)) from e
RuntimeError: DataLoader worker (pid(s) 22128) exited unexpectedly
[2023-11-07 08:46:08,033][flwr][ERROR] - [36mray::launch_and_evaluate()[39m (pid=20844, ip=127.0.0.1)
  File "C:\Users\Admin\anaconda3\envs\flwrpytorch\lib\multiprocessing\queues.py", line 108, in get
    raise Empty
_queue.Empty

The above exception was the direct cause of the following exception:

[36mray::launch_and_evaluate()[39m (pid=20844, ip=127.0.0.1)
  File "python\ray\_raylet.pyx", line 633, in ray._raylet.execute_task
  File "python\ray\_raylet.pyx", line 674, in ray._raylet.execute_task
  File "python\ray\_raylet.pyx", line 640, in ray._raylet.execute_task
  File "python\ray\_raylet.pyx", line 644, in ray._raylet.execute_task
  File "C:\Users\Admin\anaconda3\envs\flwrpytorch\lib\site-packages\flwr\simulation\ray_transport\ray_client_proxy.py", line 160, in launch_and_evaluate
    return maybe_call_evaluate(
  File "C:\Users\Admin\anaconda3\envs\flwrpytorch\lib\site-packages\flwr\client\client.py", line 205, in maybe_call_evaluate
    return client.evaluate(evaluate_ins)
  File "C:\Users\Admin\anaconda3\envs\flwrpytorch\lib\site-packages\flwr\client\app.py", line 321, in _evaluate
    results = self.numpy_client.evaluate(parameters, ins.config)  # type: ignore
  File "c:\Users\Admin\Desktop\Vipul\drive-download-20230927T134210Z-001\client.py", line 79, in evaluate
    loss, accuracy = test(self.model, self.valloader, self.device)
  File "c:\Users\Admin\Desktop\Vipul\drive-download-20230927T134210Z-001\model.py", line 57, in test
    for data in testloader:
  File "C:\Users\Admin\anaconda3\envs\flwrpytorch\lib\site-packages\torch\utils\data\dataloader.py", line 628, in __next__
    data = self._next_data()
  File "C:\Users\Admin\anaconda3\envs\flwrpytorch\lib\site-packages\torch\utils\data\dataloader.py", line 1316, in _next_data
    idx, data = self._get_data()
  File "C:\Users\Admin\anaconda3\envs\flwrpytorch\lib\site-packages\torch\utils\data\dataloader.py", line 1282, in _get_data
    success, data = self._try_get_data()
  File "C:\Users\Admin\anaconda3\envs\flwrpytorch\lib\site-packages\torch\utils\data\dataloader.py", line 1133, in _try_get_data
    raise RuntimeError('DataLoader worker (pid(s) {}) exited unexpectedly'.format(pids_str)) from e
RuntimeError: DataLoader worker (pid(s) 15048) exited unexpectedly
[2023-11-07 08:46:08,440][flwr][ERROR] - [36mray::launch_and_evaluate()[39m (pid=17684, ip=127.0.0.1)
  File "C:\Users\Admin\anaconda3\envs\flwrpytorch\lib\multiprocessing\queues.py", line 108, in get
    raise Empty
_queue.Empty

The above exception was the direct cause of the following exception:

[36mray::launch_and_evaluate()[39m (pid=17684, ip=127.0.0.1)
  File "python\ray\_raylet.pyx", line 633, in ray._raylet.execute_task
  File "python\ray\_raylet.pyx", line 674, in ray._raylet.execute_task
  File "python\ray\_raylet.pyx", line 640, in ray._raylet.execute_task
  File "python\ray\_raylet.pyx", line 644, in ray._raylet.execute_task
  File "C:\Users\Admin\anaconda3\envs\flwrpytorch\lib\site-packages\flwr\simulation\ray_transport\ray_client_proxy.py", line 160, in launch_and_evaluate
    return maybe_call_evaluate(
  File "C:\Users\Admin\anaconda3\envs\flwrpytorch\lib\site-packages\flwr\client\client.py", line 205, in maybe_call_evaluate
    return client.evaluate(evaluate_ins)
  File "C:\Users\Admin\anaconda3\envs\flwrpytorch\lib\site-packages\flwr\client\app.py", line 321, in _evaluate
    results = self.numpy_client.evaluate(parameters, ins.config)  # type: ignore
  File "c:\Users\Admin\Desktop\Vipul\drive-download-20230927T134210Z-001\client.py", line 79, in evaluate
    loss, accuracy = test(self.model, self.valloader, self.device)
  File "c:\Users\Admin\Desktop\Vipul\drive-download-20230927T134210Z-001\model.py", line 57, in test
    for data in testloader:
  File "C:\Users\Admin\anaconda3\envs\flwrpytorch\lib\site-packages\torch\utils\data\dataloader.py", line 628, in __next__
    data = self._next_data()
  File "C:\Users\Admin\anaconda3\envs\flwrpytorch\lib\site-packages\torch\utils\data\dataloader.py", line 1316, in _next_data
    idx, data = self._get_data()
  File "C:\Users\Admin\anaconda3\envs\flwrpytorch\lib\site-packages\torch\utils\data\dataloader.py", line 1282, in _get_data
    success, data = self._try_get_data()
  File "C:\Users\Admin\anaconda3\envs\flwrpytorch\lib\site-packages\torch\utils\data\dataloader.py", line 1133, in _try_get_data
    raise RuntimeError('DataLoader worker (pid(s) {}) exited unexpectedly'.format(pids_str)) from e
RuntimeError: DataLoader worker (pid(s) 22420) exited unexpectedly
[2023-11-07 08:46:11,376][flwr][DEBUG] - evaluate_round 1 received 10 results and 5 failures
[2023-11-07 08:46:11,376][flwr][WARNING] - No evaluate_metrics_aggregation_fn provided
[2023-11-07 08:46:11,376][flwr][DEBUG] - fit_round 2: strategy sampled 10 clients (out of 100)
